Workbook
Name Months: Ranges!$C$9:$C$21

Sheet Timesheet
B1: Synnovis Staff Timesheet - Phelbotomy
B6: Name: | C6: Qaiser Nazneen | F6: Job Title | G6: Adult Phlebotomist | M6: Adult Phlebotomist
B7: Department: Phebotomy | E7: Site: | F7: DH | M7: Paediatric Phlebotomist
M8: Phlebotomy Team Leader
B10: How to complete the form | M10: Bank Phlebotomist
B11: NB Unsocial enhancements should be recorded from 1st of the month to the last day of every month.
M12: DH
M13: GSTT
B14: Date | C14: Day (Mon - Sun) | D14: Shift | E14: Start Time | F14: Finish Time | G14: Break | H14: Authorized by | M14: PRUH
B15: =IF(DAY(EOMONTH($H$7,0))>=(ROW($B15)-14),ROW($B15)-14,"") -> 1 | C15: =IF($B15<>"",TEXT($H$7+ROW($B15)-15,"dddd"),"") -> Saturday | H15: =IF(ISNA(VLOOKUP($D15,Ranges!$C$4:$G$5,9,FALSE))," ",(VLOOKUP($D15,Ranges!$C$4:$G$5,9,FALSE)))
B16: =IF(DAY(EOMONTH($H$7,0))>=(ROW($B16)-14),ROW($B16)-14,"") -> 2 | C16: =IF($B16<>"",TEXT($H$7+ROW($B16)-15,"dddd"),"") -> Sunday | H16: =IF(ISNA(VLOOKUP($D16,Ranges!$C$4:$G$5,9,FALSE))," ",(VLOOKUP($D16,Ranges!$C$4:$G$5,9,FALSE)))
B17: =IF(DAY(EOMONTH($H$7,0))>=(ROW($B17)-14),ROW($B17)-14,"") -> 3 | C17: =IF($B17<>"",TEXT($H$7+ROW($B17)-15,"dddd"),"") -> Monday | H17: =IF(ISNA(VLOOKUP($D17,Ranges!$C$4:$G$5,9,FALSE))," ",(VLOOKUP($D17,Ranges!$C$4:$G$5,9,FALSE)))
B18: =IF(DAY(EOMONTH($H$7,0))>=(ROW($B18)-14),ROW($B18)-14,"") -> 4 | C18: =IF($B18<>"",TEXT($H$7+ROW($B18)-15,"dddd"),"") -> Tuesday | H18: =IF(ISNA(VLOOKUP($D18,Ranges!$C$4:$G$5,9,FALSE))," ",(VLOOKUP($D18,Ranges!$C$4:$G$5,9,FALSE)))
B19: =IF(DAY(EOMONTH($H$7,0))>=(ROW($B19)-14),ROW($B19)-14,"") -> 5 | C19: =IF($B19<>"",TEXT($H$7+ROW($B19)-15,"dddd"),"") -> Wednesday | G19: =IF(ISNA(VLOOKUP($D19,Ranges!$C$4:$F$5,4,FALSE))," ",(VLOOKUP($D19,Ranges!$C$4:$F$5,4,FALSE))) | H19: =IF(ISNA(VLOOKUP($D19,Ranges!$C$4:$G$5,9,FALSE))," ",(VLOOKUP($D19,Ranges!$C$4:$G$5,9,FALSE)))
B20: =IF(DAY(EOMONTH($H$7,0))>=(ROW($B20)-14),ROW($B20)-14,"") -> 6 | C20: =IF($B20<>"",TEXT($H$7+ROW($B20)-15,"dddd"),"") -> Thursday | G20: =IF(ISNA(VLOOKUP($D20,Ranges!$C$4:$F$5,4,FALSE))," ",(VLOOKUP($D20,Ranges!$C$4:$F$5,4,FALSE))) | H20: =IF(ISNA(VLOOKUP($D20,Ranges!$C$4:$G$5,9,FALSE))," ",(VLOOKUP($D20,Ranges!$C$4:$G$5,9,FALSE)))
B21: =IF(DAY(EOMONTH($H$7,0))>=(ROW($B21)-14),ROW($B21)-14,"") -> 7 | C21: =IF($B21<>"",TEXT($H$7+ROW($B21)-15,"dddd"),"") -> Friday | H21: =IF(ISNA(VLOOKUP($D21,Ranges!$C$4:$G$5,9,FALSE))," ",(VLOOKUP($D21,Ranges!$C$4:$G$5,9,FALSE)))
B22: =IF(DAY(EOMONTH($H$7,0))>=(ROW($B22)-14),ROW($B22)-14,"") -> 8 | C22: =IF($B22<>"",TEXT($H$7+ROW($B22)-15,"dddd"),"") -> Saturday | H22: =IF(ISNA(VLOOKUP($D22,Ranges!$C$4:$G$5,9,FALSE))," ",(VLOOKUP($D22,Ranges!$C$4:$G$5,9,FALSE)))
B23: =IF(DAY(EOMONTH($H$7,0))>=(ROW($B23)-14),ROW($B23)-14,"") -> 9 | C23: =IF($B23<>"",TEXT($H$7+ROW($B23)-15,"dddd"),"") -> Sunday | H23: =IF(ISNA(VLOOKUP($D23,Ranges!$C$4:$G$5,9,FALSE))," ",(VLOOKUP($D23,Ranges!$C$4:$G$5,9,FALSE)))
B24: =IF(DAY(EOMONTH($H$7,0))>=(ROW($B24)-14),ROW($B24)-14,"") -> 10 | C24: =IF($B24<>"",TEXT($H$7+ROW($B24)-15,"dddd"),"") -> Monday | H24: =IF(ISNA(VLOOKUP($D24,Ranges!$C$4:$G$5,9,FALSE))," ",(VLOOKUP($D24,Ranges!$C$4:$G$5,9,FALSE)))
B25: =IF(DAY(EOMONTH($H$7,0))>=(ROW($B25)-14),ROW($B25)-14,"") -> 11 | C25: =IF($B25<>"",TEXT($H$7+ROW($B25)-15,"dddd"),"") -> Tuesday | H25: =IF(ISNA(VLOOKUP($D25,Ranges!$C$4:$G$5,9,FALSE))," ",(VLOOKUP($D25,Ranges!$C$4:$G$5,9,FALSE)))
B26: =IF(DAY(EOMONTH($H$7,0))>=(ROW($B26)-14),ROW($B26)-14,"") -> 12 | C26: =IF($B26<>"",TEXT($H$7+ROW($B26)-15,"dddd"),"") -> Wednesday | H26: =IF(ISNA(VLOOKUP($D26,Ranges!$C$4:$G$5,9,FALSE))," ",(VLOOKUP($D26,Ranges!$C$4:$G$5,9,FALSE)))
B27: =IF(DAY(EOMONTH($H$7,0))>=(ROW($B27)-14),ROW($B27)-14,"") -> 13 | C27: =IF($B27<>"",TEXT($H$7+ROW($B27)-15,"dddd"),"") -> Thursday | E27: =IF(ISNA(VLOOKUP($D27,Ranges!$C$4:$F$5,2,FALSE))," ",(VLOOKUP($D27,Ranges!$C$4:$F$5,2,FALSE))) | G27: =IF(ISNA(VLOOKUP($D27,Ranges!$C$4:$F$5,4,FALSE))," ",(VLOOKUP($D27,Ranges!$C$4:$F$5,4,FALSE))) | H27: =IF(ISNA(VLOOKUP($D27,Ranges!$C$4:$G$5,9,FALSE))," ",(VLOOKUP($D27,Ranges!$C$4:$G$5,9,FALSE)))
B28: =IF(DAY(EOMONTH($H$7,0))>=(ROW($B28)-14),ROW($B28)-14,"") -> 14 | C28: =IF($B28<>"",TEXT($H$7+ROW($B28)-15,"dddd"),"") -> Friday | H28: =IF(ISNA(VLOOKUP($D28,Ranges!$C$4:$G$5,9,FALSE))," ",(VLOOKUP($D28,Ranges!$C$4:$G$5,9,FALSE)))
B29: =IF(DAY(EOMONTH($H$7,0))>=(ROW($B29)-14),ROW($B29)-14,"") -> 15 | C29: =IF($B29<>"",TEXT($H$7+ROW($B29)-15,"dddd"),"") -> Saturday | E29: =IF(ISNA(VLOOKUP($D29,Ranges!$C$4:$F$5,2,FALSE))," ",(VLOOKUP($D29,Ranges!$C$4:$F$5,2,FALSE))) | F29: =IF(ISNA(VLOOKUP($D29,Ranges!$C$4:$F$5,3,FALSE))," ",(VLOOKUP($D29,Ranges!$C$4:$F$5,3,FALSE))) | G29: =IF(ISNA(VLOOKUP($D29,Ranges!$C$4:$F$5,4,FALSE))," ",(VLOOKUP($D29,Ranges!$C$4:$F$5,4,FALSE))) | H29: =IF(ISNA(VLOOKUP($D29,Ranges!$C$4:$G$5,9,FALSE))," ",(VLOOKUP($D29,Ranges!$C$4:$G$5,9,FALSE)))
B30: =IF(DAY(EOMONTH($H$7,0))>=(ROW($B30)-14),ROW($B30)-14,"") -> 16 | C30: =IF($B30<>"",TEXT($H$7+ROW($B30)-15,"dddd"),"") -> Sunday | H30: =IF(ISNA(VLOOKUP($D30,Ranges!$C$4:$G$5,9,FALSE))," ",(VLOOKUP($D30,Ranges!$C$4:$G$5,9,FALSE)))
B31: =IF(DAY(EOMONTH($H$7,0))>=(ROW($B31)-14),ROW($B31)-14,"") -> 17 | C31: =IF($B31<>"",TEXT($H$7+ROW($B31)-15,"dddd"),"") -> Monday | H31: =IF(ISNA(VLOOKUP($D31,Ranges!$C$4:$G$5,9,FALSE))," ",(VLOOKUP($D31,Ranges!$C$4:$G$5,9,FALSE)))
B32: =IF(DAY(EOMONTH($H$7,0))>=(ROW($B32)-14),ROW($B32)-14,"") -> 18 | C32: =IF($B32<>"",TEXT($H$7+ROW($B32)-15,"dddd"),"") -> Tuesday | H32: =IF(ISNA(VLOOKUP($D32,Ranges!$C$4:$G$5,9,FALSE))," ",(VLOOKUP($D32,Ranges!$C$4:$G$5,9,FALSE)))
B33: =IF(DAY(EOMONTH($H$7,0))>=(ROW($B33)-14),ROW($B33)-14,"") -> 19 | C33: =IF($B33<>"",TEXT($H$7+ROW($B33)-15,"dddd"),"") -> Wednesday | H33: =IF(ISNA(VLOOKUP($D33,Ranges!$C$4:$G$5,9,FALSE))," ",(VLOOKUP($D33,Ranges!$C$4:$G$5,9,FALSE)))
B34: =IF(DAY(EOMONTH($H$7,0))>=(ROW($B34)-14),ROW($B34)-14,"") -> 20 | C34: =IF($B34<>"",TEXT($H$7+ROW($B34)-15,"dddd"),"") -> Thursday | H34: =IF(ISNA(VLOOKUP($D34,Ranges!$C$4:$G$5,9,FALSE))," ",(VLOOKUP($D34,Ranges!$C$4:$G$5,9,FALSE)))
B35: =IF(DAY(EOMONTH($H$7,0))>=(ROW($B35)-14),ROW($B35)-14,"") -> 21 | C35: =IF($B35<>"",TEXT($H$7+ROW($B35)-15,"dddd"),"") -> Friday | H35: =IF(ISNA(VLOOKUP($D35,Ranges!$C$4:$G$5,9,FALSE))," ",(VLOOKUP($D35,Ranges!$C$4:$G$5,9,FALSE)))
B36: =IF(DAY(EOMONTH($H$7,0))>=(ROW($B36)-14),ROW($B36)-14,"") -> 22 | C36: =IF($B36<>"",TEXT($H$7+ROW($B36)-15,"dddd"),"") -> Saturday | G36: =IF(ISNA(VLOOKUP($D36,Ranges!$C$4:$F$5,4,FALSE))," ",(VLOOKUP($D36,Ranges!$C$4:$F$5,4,FALSE))) | H36: =IF(ISNA(VLOOKUP($D36,Ranges!$C$4:$G$5,9,FALSE))," ",(VLOOKUP($D36,Ranges!$C$4:$G$5,9,FALSE)))
B37: =IF(DAY(EOMONTH($H$7,0))>=(ROW($B37)-14),ROW($B37)-14,"") -> 23 | C37: =IF($B37<>"",TEXT($H$7+ROW($B37)-15,"dddd"),"") -> Sunday | H37: =IF(ISNA(VLOOKUP($D37,Ranges!$C$4:$G$5,9,FALSE))," ",(VLOOKUP($D37,Ranges!$C$4:$G$5,9,FALSE)))
B38: =IF(DAY(EOMONTH($H$7,0))>=(ROW($B38)-14),ROW($B38)-14,"") -> 24 | C38: =IF($B38<>"",TEXT($H$7+ROW($B38)-15,"dddd"),"") -> Monday | G38: =IF(ISNA(VLOOKUP($D38,Ranges!$C$4:$F$5,4,FALSE))," ",(VLOOKUP($D38,Ranges!$C$4:$F$5,4,FALSE))) | H38: =IF(ISNA(VLOOKUP($D38,Ranges!$C$4:$G$5,9,FALSE))," ",(VLOOKUP($D38,Ranges!$C$4:$G$5,9,FALSE)))
B39: =IF(DAY(EOMONTH($H$7,0))>=(ROW($B39)-14),ROW($B39)-14,"") -> 25 | C39: =IF($B39<>"",TEXT($H$7+ROW($B39)-15,"dddd"),"") -> Tuesday | G39: =IF(ISNA(VLOOKUP($D39,Ranges!$C$4:$F$5,4,FALSE))," ",(VLOOKUP($D39,Ranges!$C$4:$F$5,4,FALSE))) | H39: =IF(ISNA(VLOOKUP($D39,Ranges!$C$4:$G$5,9,FALSE))," ",(VLOOKUP($D39,Ranges!$C$4:$G$5,9,FALSE)))
B40: =IF(DAY(EOMONTH($H$7,0))>=(ROW($B40)-14),ROW($B40)-14,"") -> 26 | C40: =IF($B40<>"",TEXT($H$7+ROW($B40)-15,"dddd"),"") -> Wednesday | H40: =IF(ISNA(VLOOKUP($D40,Ranges!$C$4:$G$5,9,FALSE))," ",(VLOOKUP($D40,Ranges!$C$4:$G$5,9,FALSE)))
B41: =IF(DAY(EOMONTH($H$7,0))>=(ROW($B41)-14),ROW($B41)-14,"") -> 27 | C41: =IF($B41<>"",TEXT($H$7+ROW($B41)-15,"dddd"),"") -> Thursday | H41: =IF(ISNA(VLOOKUP($D41,Ranges!$C$4:$G$5,9,FALSE))," ",(VLOOKUP($D41,Ranges!$C$4:$G$5,9,FALSE)))
B42: =IF(DAY(EOMONTH($H$7,0))>=(ROW($B42)-14),ROW($B42)-14,"") -> 28 | C42: =IF($B42<>"",TEXT($H$7+ROW($B42)-15,"dddd"),"") -> Friday | E42: =IF(ISNA(VLOOKUP($D42,Ranges!$C$4:$F$5,2,FALSE))," ",(VLOOKUP($D42,Ranges!$C$4:$F$5,2,FALSE))) | F42: =IF(ISNA(VLOOKUP($D42,Ranges!$C$4:$F$5,3,FALSE))," ",(VLOOKUP($D42,Ranges!$C$4:$F$5,3,FALSE))) | G42: =IF(ISNA(VLOOKUP($D42,Ranges!$C$4:$F$5,4,FALSE))," ",(VLOOKUP($D42,Ranges!$C$4:$F$5,4,FALSE))) | H42: =IF(ISNA(VLOOKUP($D42,Ranges!$C$4:$G$5,9,FALSE))," ",(VLOOKUP($D42,Ranges!$C$4:$G$5,9,FALSE)))
B43: =IF(DAY(EOMONTH($H$7,0))>=(ROW($B43)-14),ROW($B43)-14,"") -> 29 | C43: =IF($B43<>"",TEXT($H$7+ROW($B43)-15,"dddd"),"") -> Saturday | G43: =IF(ISNA(VLOOKUP($D43,Ranges!$C$4:$F$5,4,FALSE))," ",(VLOOKUP($D43,Ranges!$C$4:$F$5,4,FALSE))) | H43: =IF(ISNA(VLOOKUP($D43,Ranges!$C$4:$G$5,9,FALSE))," ",(VLOOKUP($D43,Ranges!$C$4:$G$5,9,FALSE)))
B44: =IF(DAY(EOMONTH($H$7,0))>=(ROW($B44)-14),ROW($B44)-14,"") -> 30 | C44: =IF($B44<>"",TEXT($H$7+ROW($B44)-15,"dddd"),"") -> Sunday | H44: =IF(ISNA(VLOOKUP($D44,Ranges!$C$4:$G$5,9,FALSE))," ",(VLOOKUP($D44,Ranges!$C$4:$G$5,9,FALSE)))
B45: =IF(DAY(EOMONTH($H$7,0))>=(ROW($B45)-14),ROW($B45)-14,"") -> 31 | C45: =IF($B45<>"",TEXT($H$7+ROW($B45)-15,"dddd"),"") -> Monday | G45: =IF(ISNA(VLOOKUP($D45,Ranges!$C$4:$F$5,4,FALSE))," ",(VLOOKUP($D45,Ranges!$C$4:$F$5,4,FALSE))) | H45: =IF(ISNA(VLOOKUP($D45,Ranges!$C$4:$G$5,9,FALSE))," ",(VLOOKUP($D45,Ranges!$C$4:$G$5,9,FALSE)))
...

Sheet Ranges
C4: Shift | D4: Start Time | E4: Finish Time | F4: Break | G4: OVERTIME
C5: Overtime (Enter Hours Worked) | D5: ? | E5: ? | F5: ? | G5: ?
C9: =EOMONTH(TODAY(),ROW($C9)-16)+1 -> 46054 | G9: Adult Phelobotomist
C10: =EOMONTH(TODAY(),ROW($C10)-16)+1 -> 46082 | G10: Paedatric Phelobotomist
C11: =EOMONTH(TODAY(),ROW($C11)-16)+1 -> 46113 | G11: Phelbotomy Team Leader
C12: =EOMONTH(TODAY(),ROW($C12)-16)+1 -> 46143 | G12: Bank Phelbotomist
C13: =EOMONTH(TODAY(),ROW($C13)-16)+1 -> 46174
C14: =EOMONTH(TODAY(),ROW($C14)-16)+1 -> 46204
C15: =EOMONTH(TODAY(),ROW($C15)-16)+1 -> 46235
C16: =EOMONTH(TODAY(),ROW($C16)-16)+1 -> 46266
C17: =EOMONTH(TODAY(),ROW($C17)-16)+1 -> 46296
C18: =EOMONTH(TODAY(),ROW($C18)-16)+1 -> 46327
C19: =EOMONTH(TODAY(),ROW($C19)-16)+1 -> 46357
C20: =EOMONTH(TODAY(),ROW($C20)-16)+1 -> 46388
C21: =EOMONTH(TODAY(),ROW($C21)-16)+1 -> 46419
